2016-09-28 19:30:53 - DEBUG - commonhelper - writeToLogFile - at line:  127  - CommonHelp: leaving writeToLogFile
2016-09-28 19:30:53 - INFO - Start - info - at line:  47  - Starting script to parse  and run the test
2016-09-28 19:30:53 - DEBUG - Start - testcaseRunner - at line:  168  - Inside ThreadPoolExecutor try block()
2016-09-28 19:30:53 - DEBUG - Start - sequential_task - at line:  147  - Inside sequential_task()
2016-09-28 19:30:53 - INFO - Start - Task_API - at line:  84  - Start API test cases
2016-09-28 19:30:53 - DEBUG - Start - get_test_cases - at line:  113  - Start: Inside get_test_cases
2016-09-28 19:30:53 - DEBUG - Start - get_test_cases - at line:  130  - Start: Leaving get_test_cases
2016-09-28 19:30:53 - DEBUG - Start - executetestcasenew - at line:  51  - Inside executetestcasenew.
2016-09-28 19:30:53 - INFO - Start - executetestcasenew - at line:  63  - Executing Test Case testcases\TC_001.py in C:\Users\msoni1\workspace\Daft_Assessment\TestCase\API_TC\
2016-09-28 19:30:54 - INFO - Start - executetestcasenew - at line:  70  - testcases\TC_001.py script passed
2016-09-28 19:30:59 - INFO - Start - executetestcasenew - at line:  63  - Executing Test Case testcases\TC_002.py in C:\Users\msoni1\workspace\Daft_Assessment\TestCase\API_TC\
2016-09-28 19:31:00 - INFO - Start - executetestcasenew - at line:  70  - testcases\TC_002.py script passed
2016-09-28 19:31:05 - INFO - Start - executetestcasenew - at line:  63  - Executing Test Case testcases\TC_003.py in C:\Users\msoni1\workspace\Daft_Assessment\TestCase\API_TC\
2016-09-28 19:31:06 - INFO - Start - executetestcasenew - at line:  73  - testcases\TC_003.py script failed
2016-09-28 19:31:11 - INFO - Start - executetestcasenew - at line:  63  - Executing Test Case testcases\TC_004.py in C:\Users\msoni1\workspace\Daft_Assessment\TestCase\API_TC\
2016-09-28 19:31:12 - INFO - Start - executetestcasenew - at line:  73  - testcases\TC_004.py script failed
2016-09-28 19:31:17 - INFO - Start - executetestcasenew - at line:  63  - Executing Test Case testcases\TC_005.py in C:\Users\msoni1\workspace\Daft_Assessment\TestCase\API_TC\
2016-09-28 19:31:19 - INFO - Start - executetestcasenew - at line:  70  - testcases\TC_005.py script passed
2016-09-28 19:31:24 - DEBUG - Start - executetestcasenew - at line:  79  - Leaving executetestcasenew.
2016-09-28 19:31:24 - INFO - Start - Task_UI - at line:  93  - Start UI test cases
2016-09-28 19:31:24 - DEBUG - Start - get_test_cases - at line:  113  - Start: Inside get_test_cases
2016-09-28 19:31:24 - DEBUG - Start - get_test_cases - at line:  130  - Start: Leaving get_test_cases
2016-09-28 19:31:24 - DEBUG - Start - executetestcasenew - at line:  51  - Inside executetestcasenew.
2016-09-28 19:31:24 - INFO - Start - executetestcasenew - at line:  63  - Executing Test Case uitestcases\TC_01_OpenDaftWebSite.py in C:\Users\msoni1\workspace\Daft_Assessment\TestCase\UI_TC\
2016-09-28 19:31:39 - INFO - Start - executetestcasenew - at line:  70  - uitestcases\TC_01_OpenDaftWebSite.py script passed
2016-09-28 19:31:44 - INFO - Start - executetestcasenew - at line:  63  - Executing Test Case uitestcases\TC_02_EndToEndScenario.py in C:\Users\msoni1\workspace\Daft_Assessment\TestCase\UI_TC\
2016-09-28 19:34:08 - INFO - Start - executetestcasenew - at line:  70  - uitestcases\TC_02_EndToEndScenario.py script passed
2016-09-28 19:34:13 - DEBUG - Start - executetestcasenew - at line:  79  - Leaving executetestcasenew.
2016-09-28 19:34:13 - DEBUG - Start - sequential_task - at line:  151  - Leaving sequential_task()
2016-09-28 19:34:13 - DEBUG - Start - testcaseRunner - at line:  191  - Leaving ThreadPoolExecutor try block()
